<robot
  name="robot">
  <link
    name="base_link">
    <inertial>
      <origin
        xyz="-0.000264760661064783 0.00664648963349924 0.000264762912808713"
        rpy="0 0 0" />
      <mass
        value="1.15919256315212" />
      <inertia
        ixx="0.0067094003476943"
        ixy="-2.34510261921351E-06"
        ixz="2.76425784672043E-05"
        iyy="0.0107618075316179"
        iyz="2.34511530954424E-06"
        izz="0.00471279526237124" />
    </inertial>
    <visual>
      <origin
        xyz="0 0 0"
        rpy="0 0 0" />
      <geometry>
        <mesh
          filename="package://robot/meshes/base_link.STL" />
      </geometry>
      <material
        name="">
        <color
          rgba="1 1 1 0.3" />
      </material>
    </visual>
    <collision>
      <origin
        xyz="0 0 0"
        rpy="0 0 0" />
      <geometry>
        <mesh
          filename="package://robot/meshes/base_link_col.STL" />
      </geometry>
    </collision>
  </link>
  <link
    name="FLWheel">
    <inertial>
      <origin
        xyz="0.00388945308315219 4.79531763399738E-06 -1.38067043967127E-06"
        rpy="0 0 0" />
      <mass
        value="0.0736541264322109" />
      <inertia
        ixx="2.77194970489744E-05"
        ixy="-3.49012075170458E-09"
        ixz="9.77296011958984E-10"
        iyy="1.93054417330485E-05"
        iyz="-8.00993708107148E-10"
        izz="1.93080458554619E-05" />
    </inertial>
    <visual>
      <origin
        xyz="0 0 0"
        rpy="0 0 0" />
      <geometry>
        <mesh
          filename="package://robot/meshes/FLWheel.STL" />
      </geometry>
      <material
        name="">
        <color
          rgba="0.752941176470588 0.752941176470588 0.752941176470588 1" />
      </material>
    </visual>
    <collision>
      <origin
        xyz="0 0 0"
        rpy="0 0 0" />
      <geometry>
        <mesh
          filename="package://robot/meshes/FLWheel_col.STL" />
      </geometry>
    </collision>
  </link>
  <joint
    name="FLWheelCont"
    type="continuous">
    <origin
      xyz="0.1171 -0.099064 -0.040162"
      rpy="1.5708 0 0" />
    <parent
      link="base_link" />
    <child
      link="FLWheel" />
    <axis
      xyz="1 0 0" />
  </joint>
  <link
    name="FRWheel">
    <inertial>
      <origin
        xyz="-0.238089456274567 3.97925711011909E-06 2.9933165490853E-06"
        rpy="0 0 0" />
      <mass
        value="0.0736541281508339" />
      <inertia
        ixx="2.77194939807717E-05"
        ixy="2.89824828067423E-09"
        ixz="2.20292420934118E-09"
        iyy="1.93063135407214E-05"
        iyz="1.46689816627202E-09"
        izz="1.93071731398088E-05" />
    </inertial>
    <visual>
      <origin
        xyz="0 0 0"
        rpy="0 0 0" />
      <geometry>
        <mesh
          filename="package://robot/meshes/FRWheel.STL" />
      </geometry>
      <material
        name="">
        <color
          rgba="0.752941176470588 0.752941176470588 0.752941176470588 1" />
      </material>
    </visual>
    <collision>
      <origin
        xyz="0 0 0"
        rpy="0 0 0" />
      <geometry>
        <mesh
          filename="package://robot/meshes/FRWheel_col.STL" />
      </geometry>
    </collision>
  </link>
  <joint
    name="FRWheelCont"
    type="continuous">
    <origin
      xyz="0.1171 -0.09906355201 -0.0401615"
      rpy="1.5707963267949 0 0" />
    <parent
      link="base_link" />
    <child
      link="FRWheel" />
    <axis
      xyz="1 0 0" />
  </joint>
  <link
    name="BLWheel">
    <inertial>
      <origin
        xyz="0.00388945627456712 3.97925711014685E-06 -2.99331654884938E-06"
        rpy="0 0 0" />
      <mass
        value="0.0736541281508339" />
      <inertia
        ixx="2.77194939807717E-05"
        ixy="-2.89824828068812E-09"
        ixz="2.2029242093398E-09"
        iyy="1.93063135407214E-05"
        iyz="-1.46689816627361E-09"
        izz="1.93071731398088E-05" />
    </inertial>
    <visual>
      <origin
        xyz="0 0 0"
        rpy="0 0 0" />
      <geometry>
        <mesh
          filename="package://robot/meshes/BLWheel.STL" />
      </geometry>
      <material
        name="">
        <color
          rgba="0.752941176470588 0.752941176470588 0.752941176470588 1" />
      </material>
    </visual>
    <collision>
      <origin
        xyz="0 0 0"
        rpy="0 0 0" />
      <geometry>
        <mesh
          filename="package://robot/meshes/BLWheel_col.STL" />
      </geometry>
    </collision>
  </link>
  <joint
    name="BLWheelCont"
    type="continuous">
    <origin
      xyz="0.1171 0.0990635520100003 -0.0401615"
      rpy="1.5707963267949 0 0" />
    <parent
      link="base_link" />
    <child
      link="BLWheel" />
    <axis
      xyz="0 0 0" />
  </joint>
  <link
    name="BRWheel">
    <inertial>
      <origin
        xyz="-0.00636445308315207 4.79531763405289E-06 1.38067043978229E-06"
        rpy="0 0 0" />
      <mass
        value="0.0736541264322109" />
      <inertia
        ixx="2.77194970489743E-05"
        ixy="3.49012075168172E-09"
        ixz="9.77296011957692E-10"
        iyy="1.93054417330485E-05"
        iyz="8.00993708090894E-10"
        izz="1.93080458554619E-05" />
    </inertial>
    <visual>
      <origin
        xyz="0 0 0"
        rpy="0 0 0" />
      <geometry>
        <mesh
          filename="package://robot/meshes/BRWheel.STL" />
      </geometry>
      <material
        name="">
        <color
          rgba="0.752941176470588 0.752941176470588 0.752941176470588 1" />
      </material>
    </visual>
    <collision>
      <origin
        xyz="0 0 0"
        rpy="0 0 0" />
      <geometry>
        <mesh
          filename="package://robot/meshes/BRWheel_col.STL" />
      </geometry>
    </collision>
  </link>
  <joint
    name="BRWheelCont"
    type="continuous">
    <origin
      xyz="-0.114625 0.09906355201 -0.0401615"
      rpy="1.5707963267949 0 0" />
    <parent
      link="base_link" />
    <child
      link="BRWheel" />
    <axis
      xyz="1 0 0" />
  </joint>
  <link
    name="ArmYRot">
    <inertial>
      <origin
        xyz="0.000681964404144919 0.0310539448648574 -0.0127837530436466"
        rpy="0 0 0" />
      <mass
        value="0.571743531126574" />
      <inertia
        ixx="0.00130664575781196"
        ixy="2.01805366799632E-05"
        ixz="2.44737795526061E-06"
        iyy="0.00169284950533526"
        iyz="5.18921274682049E-05"
        izz="0.00108415740916047" />
    </inertial>
    <visual>
      <origin
        xyz="0 0 0"
        rpy="0 0 0" />
      <geometry>
        <mesh
          filename="package://robot/meshes/ArmYRot.STL" />
      </geometry>
      <material
        name="">
        <color
          rgba="0.666666666666667 0.694117647058824 0.764705882352941 1" />
      </material>
    </visual>
    <collision>
      <origin
        xyz="0 0 0"
        rpy="0 0 0" />
      <geometry>
        <mesh
          filename="package://robot/meshes/ArmYRot_col.STL" />
      </geometry>
    </collision>
  </link>
  <joint
    name="ArmYRotCont"
    type="continuous">
    <origin
      xyz="0 0 0.02266"
      rpy="1.5708 -4.2993E-16 -0.7854" />
    <parent
      link="base_link" />
    <child
      link="ArmYRot" />
    <axis
      xyz="0 -1 0" />
  </joint>
  <link
    name="ArmRot1">
    <inertial>
      <origin
        xyz="0.00851780401293389 0.0652472578677626 0.0130718014658456"
        rpy="0 0 0" />
      <mass
        value="0.247629627425225" />
      <inertia
        ixx="0.00083952384826181"
        ixy="5.66840333807547E-05"
        ixz="-2.23733251784933E-05"
        iyy="0.000383812124258634"
        iyz="0.000139676728992712"
        izz="0.000756587555727813" />
    </inertial>
    <visual>
      <origin
        xyz="0 0 0"
        rpy="0 0 0" />
      <geometry>
        <mesh
          filename="package://robot/meshes/ArmRot1.STL" />
      </geometry>
      <material
        name="">
        <color
          rgba="0.666666666666667 0.694117647058824 0.764705882352941 1" />
      </material>
    </visual>
    <collision>
      <origin
        xyz="0 0 0"
        rpy="0 0 0" />
      <geometry>
        <mesh
          filename="package://robot/meshes/ArmRot1_col.STL" />
      </geometry>
    </collision>
  </link>
  <joint
    name="ArmRot1Rev"
    type="revolute">
    <origin
      xyz="1.143E-05 0.057267 0.020728"
      rpy="-7.3956E-32 -1.1102E-16 1.7931E-21" />
    <parent
      link="ArmYRot" />
    <child
      link="ArmRot1" />
    <axis
      xyz="1 0 0" />
    <limit
      lower="0"
      upper="0"
      effort="10"
      velocity="1" />
  </joint>
  <link
    name="ArmRot2">
    <inertial>
      <origin
        xyz="0.00563335405046204 -0.0743495625672852 0.0774120463323625"
        rpy="0 0 0" />
      <mass
        value="0.274282093236145" />
      <inertia
        ixx="0.00181284257514748"
        ixy="5.21711953619901E-05"
        ixz="8.55557751729304E-06"
        iyy="0.000875758646833159"
        iyz="-0.000829845988777018"
        izz="0.00111595357767381" />
    </inertial>
    <visual>
      <origin
        xyz="0 0 0"
        rpy="0 0 0" />
      <geometry>
        <mesh
          filename="package://robot/meshes/ArmRot2.STL" />
      </geometry>
      <material
        name="">
        <color
          rgba="0.666666666666667 0.694117647058824 0.764705882352941 1" />
      </material>
    </visual>
    <collision>
      <origin
        xyz="0 0 0"
        rpy="0 0 0" />
      <geometry>
        <mesh
          filename="package://robot/meshes/ArmRot2_col.STL" />
      </geometry>
    </collision>
  </link>
  <joint
    name="ArmRot2Rev"
    type="revolute">
    <origin
      xyz="-1.143E-05 0.13289 0.065139"
      rpy="4.9304E-32 0 6.1824E-18" />
    <parent
      link="ArmRot1" />
    <child
      link="ArmRot2" />
    <axis
      xyz="1 0 0" />
    <limit
      lower="0"
      upper="0"
      effort="10"
      velocity="1" />
  </joint>

  <gazebo reference="FLWheel">
      <material>Gazebo/Gold</material>
  </gazebo>
  <gazebo reference="FRWheel">
      <material>Gazebo/Gold</material>
  </gazebo>
  <gazebo reference="BLWheel">
      <material>Gazebo/Gold</material>
  </gazebo>
  <gazebo reference="BRWheel">
      <material>Gazebo/Gold</material>
  </gazebo>

  <gazebo reference="base_link">
      <material>Gazebo/Blue</material>
  </gazebo>

  <gazebo reference="ArmYRot">
      <material>Gazebo/Gold</material>
  </gazebo>
  <gazebo reference="ArmRot1">
      <material>Gazebo/Blue</material>
  </gazebo>
  <gazebo reference="ArmRot2">
      <material>Gazebo/Gold</material>
  </gazebo>

  <gazebo>
      <plugin name="object_controller" filename="libgazebo_ros_planar_move.so">
        <commandTopic>desired_velocity</commandTopic>
        <odometryTopic>odom</odometryTopic>
        <odometryFrame>odom</odometryFrame>
        <odometryRate>20.0</odometryRate>
        <robotBaseFrame>base_link</robotBaseFrame>
      </plugin>
 </gazebo>

</robot>

